Workbook
Name ListeMois: REEL!$K$8:$K$19
Name ListeMois: BUDGET!$K$8:$K$19
Name ListeProduits: REEL!$K$2:$K$4
Name ListeProduits: BUDGET!$K$2:$K$4
Name ListeRegions: REEL!$K$23:$K$26
Name ListeRegions: BUDGET!$K$23:$K$26

Sheet README
B2: Norelec Industries - Suivi budgétaire 2025
B4: Périmètre : Projet 1 = budget vs réel 2025 (4 régions, 3 gammes de produits). Projet 3 = rentabilité par produit et par client (jeu de données distinct).
B8: Onglet | C8: Contenu
B9: BUDGET | C9: Budget 2025 par mois, région et produit
B10: REEL | C10: Réalisé 2025, même structure
B11: Consolide | C11: Budget et réel regroupés dans une table
B12: Dashboard | C12: CA budget vs réel et écarts
B13: Dashboard_Coût | C13: Coûts matières budget vs réel
B14: ANALYSE_VPM | C14: Écart de CA : effets prix, volume, mix
B15: ANALYSE_MARGE | C15: Marge et taux de marge par produit
B16: SYNTHESE | C16: Constats et recommandations (Projet 1)
B17: CLIENTS | C17: Référentiel clients
B18: VENTES | C18: 60 commandes avec marge
B19: Analyse_Rentabilité_Produit | C19: Rentabilité par produit
... B21: Synthèse_Rentabilité | C21: Constats et recommandations (Projet 3)
B23: Limites :
B24: - Données simulées, une seule année.
B25: - Hypothèses de coûts du budget saisies dans les formules de BUDGET (65 % matières, 35 % MO du coût unitaire ; charges fixes à 8 % du CA).
B26: - Pas de prévision dans ce classeur.

Sheet SYNTHESE
A1: (Norelec Industries — Analyse Budget vs Réel 2025)
B4: 1. Constat global
B5: Constat global : Le CA réel est proche du budget sur l'année (5 788 883 € vs 5 784 490 €, écart de +0,08 %), ce qui masque des écarts de sens opposé entre régions : Export est inférieur au budget de 22 493 € (−2,4 %), compensé par IDF, Nord et Sud (+26 887 € au total). L'analyse globale seule aurait donné une fausse impression de stabilité.
B7: 2. Alerte n°1 — Rentabilité Composants
B8: Alerte n°1 : Malgré un CA en hausse (+15 766 €, porté par un effet volume positif), la marge de la gamme Composants a reculé de 28 537 € (−1,19 point de taux de marge). Cause identifiée : un surcoût matières premières concentré sur avril, mai et juin (environ +10 % par unité par rapport au coût standard).
B9: → Recommandation : sécuriser les approvisionnements matières via un contrat-cadre à prix fixe ou une couverture achat, pour limiter l'exposition à la volatilité des prix sur ce trimestre.
B11: 3. Alerte n°2 — Volume Export
B12: Alerte n°2 : La région Export affiche un écart de CA de −18,6 % sur le seul mois de juillet (moins de 3,5 % en valeur absolue le reste de l'année), cohérent avec une rupture ponctuelle plutôt qu'une tendance de fond.
B13: → Recommandation : investiguer la cause opérationnelle précise (perte de distributeur, retard logistique) et évaluer si un plan de relance commercial est nécessaire sur ce marché au T4.
B15: 4. Point de vigilance — Effet mix défavorable
B16: Point de vigilance : La croissance du volume global (+449 unités, +35 441 € en théorie, au prix moyen budget) s'est concentrée sur le produit au prix unitaire le plus faible (Composants, environ 45 € l'unité), ce qui a partiellement neutralisé le gain attendu.
B17: → Recommandation : suivre le mix produit mensuellement, pas seulement le CA total, pour détecter ce type de glissement plus tôt.

Sheet Synthèse_Rentabilité
B3: 1. Contexte
B5: Cette analyse vise à évaluer la rentabilité de Norelec Industries selon deux angles — produit et client — afin d'identifier les leviers de croissance rentable et les zones de risque à surveiller."
B7: 2. Constat Produit
B8: Modules est le produit le plus performant, combinant le CA le plus élevé (117 702 €) et un bon taux de marge (29,7 %). Composants génère un volume important (108 734 €) mais affiche le taux de marge le plus faible du
B9: portefeuille (27,7 %), ce qui appelle une vigilance si sa part continue de croître. Accessoires, à l'inverse, présente le meilleur taux de marge (30,1 %) mais reste le plus petit contributeur en valeur (63 023 €)
B10: un potentiel de croissance existe si le volume peut augmenter sans éroder la marge."
B13: 3. Constat Client
B14: Global Export Partners se distingue nettement du reste du portefeuille : il génère le CA le plus élevé (35 917 €) mais avec le taux de marge le plus faible (27,1 %), soit l'écart le plus marqué de tous les clients analysés
B15: Les neuf autres clients affichent des taux de marge homogènes, compris entre 28,5 % et 30,5 %, ne révélant pas de risque de concentration particulier sur ce segment."
B19: 4. Recommandation
B20: Il est recommandé d'investiguer les conditions commerciales accordées à Global Export Partners — remise volume, structure tarifaire à l'export, ou mix produit spécifique
B21: — afin de comprendre l'origine de sa faible rentabilité et d'évaluer une renégociation si pertinent
... B23: plutôt que Composants dont la marge plus faible limite la contribution malgré un volume élevé.

Sheet BUDGET
A1: Mois | B1: N_Mois | C1: Région | D1: Produit | E1: Volume_Budget | F1: CA_Budget | G1: Coût Matières | H1: Coût Main d'Œuvre | I1: Charges Fixes | K1: Produit | L1: Volume_Base | M1: Prix_Unitaire | N1: Coût_Unitaire
A2: Janvier | B2: 1 | C2: IDF | D2: composants | E2: =ROUND(VLOOKUP($D2,$K$2:$N$4,2,FALSE)*VLOOKUP($A2,$K$8:$L$19,2,FALSE)*VLOOKUP($C2,$K$23:$L$26,2,FALSE),0) -> 1778 | F2: =E2*VLOOKUP($D2,$K$2:$N$4,3,FALSE) -> 80010 | G2: =E2*VLOOKUP($D2,$K$2:$N$4,4,FALSE)*0.65 -> 32359.6 | H2: =E2*VLOOKUP($D2,$K$2:$N$4,4,FALSE)*0.35 -> 17424.4 | I2: =F2*0.08 -> 6400.8 | K2: composants | L2: 5200 | M2: 45 | N2: 28
A3: Janvier | B3: 1 | C3: Nord | D3: composants | E3: =ROUND(VLOOKUP($D3,$K$2:$N$4,2,FALSE)*VLOOKUP($A3,$K$8:$L$19,2,FALSE)*VLOOKUP($C3,$K$23:$L$26,2,FALSE),0) -> 1123 | F3: =E3*VLOOKUP($D3,$K$2:$N$4,3,FALSE) -> 50535 | G3: =E3*VLOOKUP($D3,$K$2:$N$4,4,FALSE)*0.65 -> 20438.6 | H3: =E3*VLOOKUP($D3,$K$2:$N$4,4,FALSE)*0.35 -> 11005.4 | I3: =F3*0.08 -> 4042.8 | K3: Equipements | L3: 620 | M3: 320 | N3: 210
A4: Janvier | B4: 1 | C4: Sud | D4: composants | E4: =ROUND(VLOOKUP($D4,$K$2:$N$4,2,FALSE)*VLOOKUP($A4,$K$8:$L$19,2,FALSE)*VLOOKUP($C4,$K$23:$L$26,2,FALSE),0) -> 1030 | F4: =E4*VLOOKUP($D4,$K$2:$N$4,3,FALSE) -> 46350 | G4: =E4*VLOOKUP($D4,$K$2:$N$4,4,FALSE)*0.65 -> 18746 | H4: =E4*VLOOKUP($D4,$K$2:$N$4,4,FALSE)*0.35 -> 10094 | I4: =F4*0.08 -> 3708 | K4: Services | L4: 380 | M4: 150 | N4: 90
A5: Janvier | B5: 1 | C5: Export | D5: composants | E5: =ROUND(VLOOKUP($D5,$K$2:$N$4,2,FALSE)*VLOOKUP($A5,$K$8:$L$19,2,FALSE)*VLOOKUP($C5,$K$23:$L$26,2,FALSE),0) -> 749 | F5: =E5*VLOOKUP($D5,$K$2:$N$4,3,FALSE) -> 33705 | G5: =E5*VLOOKUP($D5,$K$2:$N$4,4,FALSE)*0.65 -> 13631.8 | H5: =E5*VLOOKUP($D5,$K$2:$N$4,4,FALSE)*0.35 -> 7340.2 | I5: =F5*0.08 -> 2696.4
A6: Janvier | B6: 1 | C6: IDF | D6: Equipements | E6: =ROUND(VLOOKUP($D6,$K$2:$N$4,2,FALSE)*VLOOKUP($A6,$K$8:$L$19,2,FALSE)*VLOOKUP($C6,$K$23:$L$26,2,FALSE),0) -> 212 | F6: =E6*VLOOKUP($D6,$K$2:$N$4,3,FALSE) -> 67840 | G6: =E6*VLOOKUP($D6,$K$2:$N$4,4,FALSE)*0.65 -> 28938 | H6: =E6*VLOOKUP($D6,$K$2:$N$4,4,FALSE)*0.35 -> 15582 | I6: =F6*0.08 -> 5427.2
A7: Janvier | B7: 1 | C7: Nord | D7: Equipements | E7: =ROUND(VLOOKUP($D7,$K$2:$N$4,2,FALSE)*VLOOKUP($A7,$K$8:$L$19,2,FALSE)*VLOOKUP($C7,$K$23:$L$26,2,FALSE),0) -> 134 | F7: =E7*VLOOKUP($D7,$K$2:$N$4,3,FALSE) -> 42880 | G7: =E7*VLOOKUP($D7,$K$2:$N$4,4,FALSE)*0.65 -> 18291 | H7: =E7*VLOOKUP($D7,$K$2:$N$4,4,FALSE)*0.35 -> 9849 | I7: =F7*0.08 -> 3430.4 | K7: Mois | L7: Facteur
A8: Janvier | B8: 1 | C8: Sud | D8: Equipements | E8: =ROUND(VLOOKUP($D8,$K$2:$N$4,2,FALSE)*VLOOKUP($A8,$K$8:$L$19,2,FALSE)*VLOOKUP($C8,$K$23:$L$26,2,FALSE),0) -> 123 | F8: =E8*VLOOKUP($D8,$K$2:$N$4,3,FALSE) -> 39360 | G8: =E8*VLOOKUP($D8,$K$2:$N$4,4,FALSE)*0.65 -> 16789.5 | H8: =E8*VLOOKUP($D8,$K$2:$N$4,4,FALSE)*0.35 -> 9040.5 | I8: =F8*0.08 -> 3148.8 | K8: Janvier | L8: 0.9
A9: Janvier | B9: 1 | C9: Export | D9: Equipements | E9: =ROUND(VLOOKUP($D9,$K$2:$N$4,2,FALSE)*VLOOKUP($A9,$K$8:$L$19,2,FALSE)*VLOOKUP($C9,$K$23:$L$26,2,FALSE),0) -> 89 | F9: =E9*VLOOKUP($D9,$K$2:$N$4,3,FALSE) -> 28480 | G9: =E9*VLOOKUP($D9,$K$2:$N$4,4,FALSE)*0.65 -> 12148.5 | H9: =E9*VLOOKUP($D9,$K$2:$N$4,4,FALSE)*0.35 -> 6541.5 | I9: =F9*0.08 -> 2278.4 | K9: Février | L9: 0.92
A10: Janvier | B10: 1 | C10: IDF | D10: Services | E10: =ROUND(VLOOKUP($D10,$K$2:$N$4,2,FALSE)*VLOOKUP($A10,$K$8:$L$19,2,FALSE)*VLOOKUP($C10,$K$23:$L$26,2,FALSE),0) -> 130 | F10: =E10*VLOOKUP($D10,$K$2:$N$4,3,FALSE) -> 19500 | G10: =E10*VLOOKUP($D10,$K$2:$N$4,4,FALSE)*0.65 -> 7605 | H10: =E10*VLOOKUP($D10,$K$2:$N$4,4,FALSE)*0.35 -> 4095 | I10: =F10*0.08 -> 1560 | K10: Mars | L10: 1
A11: Janvier | B11: 1 | C11: Nord | D11: Services | E11: =ROUND(VLOOKUP($D11,$K$2:$N$4,2,FALSE)*VLOOKUP($A11,$K$8:$L$19,2,FALSE)*VLOOKUP($C11,$K$23:$L$26,2,FALSE),0) -> 82 | F11: =E11*VLOOKUP($D11,$K$2:$N$4,3,FALSE) -> 12300 | G11: =E11*VLOOKUP($D11,$K$2:$N$4,4,FALSE)*0.65 -> 4797 | H11: =E11*VLOOKUP($D11,$K$2:$N$4,4,FALSE)*0.35 -> 2583 | I11: =F11*0.08 -> 984 | K11: Avril | L11: 1.02
A12: Janvier | B12: 1 | C12: Sud | D12: Services | E12: =ROUND(VLOOKUP($D12,$K$2:$N$4,2,FALSE)*VLOOKUP($A12,$K$8:$L$19,2,FALSE)*VLOOKUP($C12,$K$23:$L$26,2,FALSE),0) -> 75 | F12: =E12*VLOOKUP($D12,$K$2:$N$4,3,FALSE) -> 11250 | G12: =E12*VLOOKUP($D12,$K$2:$N$4,4,FALSE)*0.65 -> 4387.5 | H12: =E12*VLOOKUP($D12,$K$2:$N$4,4,FALSE)*0.35 -> 2362.5 | I12: =F12*0.08 -> 900 | K12: Mai | L12: 1.03
A13: Janvier | B13: 1 | C13: Export | D13: Services | E13: =ROUND(VLOOKUP($D13,$K$2:$N$4,2,FALSE)*VLOOKUP($A13,$K$8:$L$19,2,FALSE)*VLOOKUP($C13,$K$23:$L$26,2,FALSE),0) -> 55 | F13: =E13*VLOOKUP($D13,$K$2:$N$4,3,FALSE) -> 8250 | G13: =E13*VLOOKUP($D13,$K$2:$N$4,4,FALSE)*0.65 -> 3217.5 | H13: =E13*VLOOKUP($D13,$K$2:$N$4,4,FALSE)*0.35 -> 1732.5 | I13: =F13*0.08 -> 660 | K13: Juin | L13: 1.05
A14: Février | B14: 2 | C14: IDF | D14: composants | E14: =ROUND(VLOOKUP($D14,$K$2:$N$4,2,FALSE)*VLOOKUP($A14,$K$8:$L$19,2,FALSE)*VLOOKUP($C14,$K$23:$L$26,2,FALSE),0) -> 1818 | F14: =E14*VLOOKUP($D14,$K$2:$N$4,3,FALSE) -> 81810 | G14: =E14*VLOOKUP($D14,$K$2:$N$4,4,FALSE)*0.65 -> 33087.6 | H14: =E14*VLOOKUP($D14,$K$2:$N$4,4,FALSE)*0.35 -> 17816.4 | I14: =F14*0.08 -> 6544.8 | K14: Juillet | L14: 0.95
A15: Février | B15: 2 | C15: Nord | D15: composants | E15: =ROUND(VLOOKUP($D15,$K$2:$N$4,2,FALSE)*VLOOKUP($A15,$K$8:$L$19,2,FALSE)*VLOOKUP($C15,$K$23:$L$26,2,FALSE),0) -> 1148 | F15: =E15*VLOOKUP($D15,$K$2:$N$4,3,FALSE) -> 51660 | G15: =E15*VLOOKUP($D15,$K$2:$N$4,4,FALSE)*0.65 -> 20893.6 | H15: =E15*VLOOKUP($D15,$K$2:$N$4,4,FALSE)*0.35 -> 11250.4 | I15: =F15*0.08 -> 4132.8 | K15: Août | L15: 0.55
A16: Février | B16: 2 | C16: Sud | D16: composants | E16: =ROUND(VLOOKUP($D16,$K$2:$N$4,2,FALSE)*VLOOKUP($A16,$K$8:$L$19,2,FALSE)*VLOOKUP($C16,$K$23:$L$26,2,FALSE),0) -> 1052 | F16: =E16*VLOOKUP($D16,$K$2:$N$4,3,FALSE) -> 47340 | G16: =E16*VLOOKUP($D16,$K$2:$N$4,4,FALSE)*0.65 -> 19146.4 | H16: =E16*VLOOKUP($D16,$K$2:$N$4,4,FALSE)*0.35 -> 10309.6 | I16: =F16*0.08 -> 3787.2 | K16: Septembre | L16: 1
A17: Février | B17: 2 | C17: Export | D17: composants | E17: =ROUND(VLOOKUP($D17,$K$2:$N$4,2,FALSE)*VLOOKUP($A17,$K$8:$L$19,2,FALSE)*VLOOKUP($C17,$K$23:$L$26,2,FALSE),0) -> 765 | F17: =E17*VLOOKUP($D17,$K$2:$N$4,3,FALSE) -> 34425 | G17: =E17*VLOOKUP($D17,$K$2:$N$4,4,FALSE)*0.65 -> 13923 | H17: =E17*VLOOKUP($D17,$K$2:$N$4,4,FALSE)*0.35 -> 7497 | I17: =F17*0.08 -> 2754 | K17: Octobre | L17: 1.08
A18: Février | B18: 2 | C18: IDF | D18: Equipements | E18: =ROUND(VLOOKUP($D18,$K$2:$N$4,2,FALSE)*VLOOKUP($A18,$K$8:$L$19,2,FALSE)*VLOOKUP($C18,$K$23:$L$26,2,FALSE),0) -> 217 | F18: =E18*VLOOKUP($D18,$K$2:$N$4,3,FALSE) -> 69440 | G18: =E18*VLOOKUP($D18,$K$2:$N$4,4,FALSE)*0.65 -> 29620.5 | H18: =E18*VLOOKUP($D18,$K$2:$N$4,4,FALSE)*0.35 -> 15949.5 | I18: =F18*0.08 -> 5555.2 | K18: Novembre | L18: 1.12
A19: Février | B19: 2 | C19: Nord | D19: Equipements | E19: =ROUND(VLOOKUP($D19,$K$2:$N$4,2,FALSE)*VLOOKUP($A19,$K$8:$L$19,2,FALSE)*VLOOKUP($C19,$K$23:$L$26,2,FALSE),0) -> 137 | F19: =E19*VLOOKUP($D19,$K$2:$N$4,3,FALSE) -> 43840 | G19: =E19*VLOOKUP($D19,$K$2:$N$4,4,FALSE)*0.65 -> 18700.5 | H19: =E19*VLOOKUP($D19,$K$2:$N$4,4,FALSE)*0.35 -> 10069.5 | I19: =F19*0.08 -> 3507.2 | K19: Décembre | L19: 1.2
A20: Février | B20: 2 | C20: Sud | D20: Equipements | E20: =ROUND(VLOOKUP($D20,$K$2:$N$4,2,FALSE)*VLOOKUP($A20,$K$8:$L$19,2,FALSE)*VLOOKUP($C20,$K$23:$L$26,2,FALSE),0) -> 125 | F20: =E20*VLOOKUP($D20,$K$2:$N$4,3,FALSE) -> 40000 | G20: =E20*VLOOKUP($D20,$K$2:$N$4,4,FALSE)*0.65 -> 17062.5 | H20: =E20*VLOOKUP($D20,$K$2:$N$4,4,FALSE)*0.35 -> 9187.5 | I20: =F20*0.08 -> 3200
A21: Février | B21: 2 | C21: Export | D21: Equipements | E21: =ROUND(VLOOKUP($D21,$K$2:$N$4,2,FALSE)*VLOOKUP($A21,$K$8:$L$19,2,FALSE)*VLOOKUP($C21,$K$23:$L$26,2,FALSE),0) -> 91 | F21: =E21*VLOOKUP($D21,$K$2:$N$4,3,FALSE) -> 29120 | G21: =E21*VLOOKUP($D21,$K$2:$N$4,4,FALSE)*0.65 -> 12421.5 | H21: =E21*VLOOKUP($D21,$K$2:$N$4,4,FALSE)*0.35 -> 6688.5 | I21: =F21*0.08 -> 2329.6
A22: Février | B22: 2 | C22: IDF | D22: Services | E22: =ROUND(VLOOKUP($D22,$K$2:$N$4,2,FALSE)*VLOOKUP($A22,$K$8:$L$19,2,FALSE)*VLOOKUP($C22,$K$23:$L$26,2,FALSE),0) -> 133 | F22: =E22*VLOOKUP($D22,$K$2:$N$4,3,FALSE) -> 19950 | G22: =E22*VLOOKUP($D22,$K$2:$N$4,4,FALSE)*0.65 -> 7780.5 | H22: =E22*VLOOKUP($D22,$K$2:$N$4,4,FALSE)*0.35 -> 4189.5 | I22: =F22*0.08 -> 1596 | K22: Région | L22: Poids
A23: Février | B23: 2 | C23: Nord | D23: Services | E23: =ROUND(VLOOKUP($D23,$K$2:$N$4,2,FALSE)*VLOOKUP($A23,$K$8:$L$19,2,FALSE)*VLOOKUP($C23,$K$23:$L$26,2,FALSE),0) -> 84 | F23: =E23*VLOOKUP($D23,$K$2:$N$4,3,FALSE) -> 12600 | G23: =E23*VLOOKUP($D23,$K$2:$N$4,4,FALSE)*0.65 -> 4914 | H23: =E23*VLOOKUP($D23,$K$2:$N$4,4,FALSE)*0.35 -> 2646 | I23: =F23*0.08 -> 1008 | K23: IDF | L23: 0.38
A24: Février | B24: 2 | C24: Sud | D24: Services | E24: =ROUND(VLOOKUP($D24,$K$2:$N$4,2,FALSE)*VLOOKUP($A24,$K$8:$L$19,2,FALSE)*VLOOKUP($C24,$K$23:$L$26,2,FALSE),0) -> 77 | F24: =E24*VLOOKUP($D24,$K$2:$N$4,3,FALSE) -> 11550 | G24: =E24*VLOOKUP($D24,$K$2:$N$4,4,FALSE)*0.65 -> 4504.5 | H24: =E24*VLOOKUP($D24,$K$2:$N$4,4,FALSE)*0.35 -> 2425.5 | I24: =F24*0.08 -> 924 | K24: Nord | L24: 0.24
A25: Février | B25: 2 | C25: Export | D25: Services | E25: =ROUND(VLOOKUP($D25,$K$2:$N$4,2,FALSE)*VLOOKUP($A25,$K$8:$L$19,2,FALSE)*VLOOKUP($C25,$K$23:$L$26,2,FALSE),0) -> 56 | F25: =E25*VLOOKUP($D25,$K$2:$N$4,3,FALSE) -> 8400 | G25: =E25*VLOOKUP($D25,$K$2:$N$4,4,FALSE)*0.65 -> 3276 | H25: =E25*VLOOKUP($D25,$K$2:$N$4,4,FALSE)*0.35 -> 1764 | I25: =F25*0.08 -> 672 | K25: Sud | L25: 0.22
A26: Mars | B26: 3 | C26: IDF | D26: composants | E26: =ROUND(VLOOKUP($D26,$K$2:$N$4,2,FALSE)*VLOOKUP($A26,$K$8:$L$19,2,FALSE)*VLOOKUP($C26,$K$23:$L$26,2,FALSE),0) -> 1976 | F26: =E26*VLOOKUP($D26,$K$2:$N$4,3,FALSE) -> 88920 | G26: =E26*VLOOKUP($D26,$K$2:$N$4,4,FALSE)*0.65 -> 35963.2 | H26: =E26*VLOOKUP($D26,$K$2:$N$4,4,FALSE)*0.35 -> 19364.8 | I26: =F26*0.08 -> 7113.6 | K26: Export | L26: 0.16
A27: Mars | B27: 3 | C27: Nord | D27: composants | E27: =ROUND(VLOOKUP($D27,$K$2:$N$4,2,FALSE)*VLOOKUP($A27,$K$8:$L$19,2,FALSE)*VLOOKUP($C27,$K$23:$L$26,2,FALSE),0) -> 1248 | F27: =E27*VLOOKUP($D27,$K$2:$N$4,3,FALSE) -> 56160 | G27: =E27*VLOOKUP($D27,$K$2:$N$4,4,FALSE)*0.65 -> 22713.6 | H27: =E27*VLOOKUP($D27,$K$2:$N$4,4,FALSE)*0.35 -> 12230.4 | I27: =F27*0.08 -> 4492.8
A28: Mars | B28: 3 | C28: Sud | D28: composants | E28: =ROUND(VLOOKUP($D28,$K$2:$N$4,2,FALSE)*VLOOKUP($A28,$K$8:$L$19,2,FALSE)*VLOOKUP($C28,$K$23:$L$26,2,FALSE),0) -> 1144 | F28: =E28*VLOOKUP($D28,$K$2:$N$4,3,FALSE) -> 51480 | G28: =E28*VLOOKUP($D28,$K$2:$N$4,4,FALSE)*0.65 -> 20820.8 | H28: =E28*VLOOKUP($D28,$K$2:$N$4,4,FALSE)*0.35 -> 11211.2 | I28: =F28*0.08 -> 4118.4
A29: Mars | B29: 3 | C29: Export | D29: composants | E29: =ROUND(VLOOKUP($D29,$K$2:$N$4,2,FALSE)*VLOOKUP($A29,$K$8:$L$19,2,FALSE)*VLOOKUP($C29,$K$23:$L$26,2,FALSE),0) -> 832 | F29: =E29*VLOOKUP($D29,$K$2:$N$4,3,FALSE) -> 37440 | G29: =E29*VLOOKUP($D29,$K$2:$N$4,4,FALSE)*0.65 -> 15142.4 | H29: =E29*VLOOKUP($D29,$K$2:$N$4,4,FALSE)*0.35 -> 8153.6 | I29: =F29*0.08 -> 2995.2
A30: Mars | B30: 3 | C30: IDF | D30: Equipements | E30: =ROUND(VLOOKUP($D30,$K$2:$N$4,2,FALSE)*VLOOKUP($A30,$K$8:$L$19,2,FALSE)*VLOOKUP($C30,$K$23:$L$26,2,FALSE),0) -> 236 | F30: =E30*VLOOKUP($D30,$K$2:$N$4,3,FALSE) -> 75520 | G30: =E30*VLOOKUP($D30,$K$2:$N$4,4,FALSE)*0.65 -> 32214 | H30: =E30*VLOOKUP($D30,$K$2:$N$4,4,FALSE)*0.35 -> 17346 | I30: =F30*0.08 -> 6041.6
A31: Mars | B31: 3 | C31: Nord | D31: Equipements | E31: =ROUND(VLOOKUP($D31,$K$2:$N$4,2,FALSE)*VLOOKUP($A31,$K$8:$L$19,2,FALSE)*VLOOKUP($C31,$K$23:$L$26,2,FALSE),0) -> 149 | F31: =E31*VLOOKUP($D31,$K$2:$N$4,3,FALSE) -> 47680 | G31: =E31*VLOOKUP($D31,$K$2:$N$4,4,FALSE)*0.65 -> 20338.5 | H31: =E31*VLOOKUP($D31,$K$2:$N$4,4,FALSE)*0.35 -> 10951.5 | I31: =F31*0.08 -> 3814.4
A32: Mars | B32: 3 | C32: Sud | D32: Equipements | E32: =ROUND(VLOOKUP($D32,$K$2:$N$4,2,FALSE)*VLOOKUP($A32,$K$8:$L$19,2,FALSE)*VLOOKUP($C32,$K$23:$L$26,2,FALSE),0) -> 136 | F32: =E32*VLOOKUP($D32,$K$2:$N$4,3,FALSE) -> 43520 | G32: =E32*VLOOKUP($D32,$K$2:$N$4,4,FALSE)*0.65 -> 18564 | H32: =E32*VLOOKUP($D32,$K$2:$N$4,4,FALSE)*0.35 -> 9996 | I32: =F32*0.08 -> 3481.6
A33: Mars | B33: 3 | C33: Export | D33: Equipements | E33: =ROUND(VLOOKUP($D33,$K$2:$N$4,2,FALSE)*VLOOKUP($A33,$K$8:$L$19,2,FALSE)*VLOOKUP($C33,$K$23:$L$26,2,FALSE),0) -> 99 | F33: =E33*VLOOKUP($D33,$K$2:$N$4,3,FALSE) -> 31680 | G33: =E33*VLOOKUP($D33,$K$2:$N$4,4,FALSE)*0.65 -> 13513.5 | H33: =E33*VLOOKUP($D33,$K$2:$N$4,4,FALSE)*0.35 -> 7276.5 | I33: =F33*0.08 -> 2534.4
A34: Mars | B34: 3 | C34: IDF | D34: Services | E34: =ROUND(VLOOKUP($D34,$K$2:$N$4,2,FALSE)*VLOOKUP($A34,$K$8:$L$19,2,FALSE)*VLOOKUP($C34,$K$23:$L$26,2,FALSE),0) -> 144 | F34: =E34*VLOOKUP($D34,$K$2:$N$4,3,FALSE) -> 21600 | G34: =E34*VLOOKUP($D34,$K$2:$N$4,4,FALSE)*0.65 -> 8424 | H34: =E34*VLOOKUP($D34,$K$2:$N$4,4,FALSE)*0.35 -> 4536 | I34: =F34*0.08 -> 1728
A35: Mars | B35: 3 | C35: Nord | D35: Services | E35: =ROUND(VLOOKUP($D35,$K$2:$N$4,2,FALSE)*VLOOKUP($A35,$K$8:$L$19,2,FALSE)*VLOOKUP($C35,$K$23:$L$26,2,FALSE),0) -> 91 | F35: =E35*VLOOKUP($D35,$K$2:$N$4,3,FALSE) -> 13650 | G35: =E35*VLOOKUP($D35,$K$2:$N$4,4,FALSE)*0.65 -> 5323.5 | H35: =E35*VLOOKUP($D35,$K$2:$N$4,4,FALSE)*0.35 -> 2866.5 | I35: =F35*0.08 -> 1092
A36: Mars | B36: 3 | C36: Sud | D36: Services | E36: =ROUND(VLOOKUP($D36,$K$2:$N$4,2,FALSE)*VLOOKUP($A36,$K$8:$L$19,2,FALSE)*VLOOKUP($C36,$K$23:$L$26,2,FALSE),0) -> 84 | F36: =E36*VLOOKUP($D36,$K$2:$N$4,3,FALSE) -> 12600 | G36: =E36*VLOOKUP($D36,$K$2:$N$4,4,FALSE)*0.65 -> 4914 | H36: =E36*VLOOKUP($D36,$K$2:$N$4,4,FALSE)*0.35 -> 2646 | I36: =F36*0.08 -> 1008
A37: Mars | B37: 3 | C37: Export | D37: Services | E37: =ROUND(VLOOKUP($D37,$K$2:$N$4,2,FALSE)*VLOOKUP($A37,$K$8:$L$19,2,FALSE)*VLOOKUP($C37,$K$23:$L$26,2,FALSE),0) -> 61 | F37: =E37*VLOOKUP($D37,$K$2:$N$4,3,FALSE) -> 9150 | G37: =E37*VLOOKUP($D37,$K$2:$N$4,4,FALSE)*0.65 -> 3568.5 | H37: =E37*VLOOKUP($D37,$K$2:$N$4,4,FALSE)*0.35 -> 1921.5 | I37: =F37*0.08 -> 732
A38: Avril | B38: 4 | C38: IDF | D38: composants | E38: =ROUND(VLOOKUP($D38,$K$2:$N$4,2,FALSE)*VLOOKUP($A38,$K$8:$L$19,2,FALSE)*VLOOKUP($C38,$K$23:$L$26,2,FALSE),0) -> 2016 | F38: =E38*VLOOKUP($D38,$K$2:$N$4,3,FALSE) -> 90720 | G38: =E38*VLOOKUP($D38,$K$2:$N$4,4,FALSE)*0.65 -> 36691.2 | H38: =E38*VLOOKUP($D38,$K$2:$N$4,4,FALSE)*0.35 -> 19756.8 | I38: =F38*0.08 -> 7257.6
... A145: Décembre | B145: 12 | C145: Export | D145: Services | E145: =ROUND(VLOOKUP($D145,$K$2:$N$4,2,FALSE)*VLOOKUP($A145,$K$8:$L$19,2,FALSE)*VLOOKUP($C145,$K$23:$L$26,2,FALSE),0) -> 73 | F145: =E145*VLOOKUP($D145,$K$2:$N$4,3,FALSE) -> 10950 | G145: =E145*VLOOKUP($D145,$K$2:$N$4,4,FALSE)*0.65 -> 4270.5 | H145: =E145*VLOOKUP($D145,$K$2:$N$4,4,FALSE)*0.35 -> 2299.5 | I145: =F145*0.08 -> 876
F147: =SUM(F2:F145) -> 5784490

Sheet REEL
A1: Mois | B1: N_Mois | C1: Région | D1: Produit | E1: Volume_reel | F1: CA_Reel | G1: Coût Matières_reel | H1: Coût Main d'Œuvre reel | I1: Charges Fixes_reel | K1: Produit | L1: Volume_Base | M1: Prix_Unitaire | N1: Coût_Unitaire
A2: Janvier | B2: 1 | C2: IDF | D2: composants | E2: 1804 | F2: 79791.69 | G2: 32702.51 | H2: 18043.73 | I2: 6315.18 | K2: composants | L2: 5200 | M2: 45 | N2: 28
A3: Janvier | B3: 1 | C3: Nord | D3: composants | E3: 1123 | F3: 50291.38 | G3: 20096.43 | H3: 11240.93 | I3: 3973.54 | K3: Equipements | L3: 620 | M3: 320 | N3: 210
A4: Janvier | B4: 1 | C4: Sud | D4: composants | E4: 1011 | F4: 46357.53 | G4: 17992.31 | H4: 9946.54 | I4: 3652.28 | K4: Services | L4: 380 | M4: 150 | N4: 90
A5: Janvier | B5: 1 | C5: Export | D5: composants | E5: 729 | F5: 32813.6 | G5: 12926.24 | H5: 7153.37 | I5: 2595.01
A6: Janvier | B6: 1 | C6: IDF | D6: Equipements | E6: 219 | F6: 70576.98 | G6: 29813.15 | H6: 16233.12 | I6: 5644.62
A7: Janvier | B7: 1 | C7: Nord | D7: Equipements | E7: 133 | F7: 42465.23 | G7: 17717.96 | H7: 9906.25 | I7: 3424.2 | K7: Mois | L7: Facteur
A8: Janvier | B8: 1 | C8: Sud | D8: Equipements | E8: 127 | F8: 40550.99 | G8: 17603.09 | H8: 9152.54 | I8: 3205.13 | K8: Janvier | L8: 0.9
A9: Janvier | B9: 1 | C9: Export | D9: Equipements | E9: 88 | F9: 27947.03 | G9: 11991.17 | H9: 6442.79 | I9: 2295.97 | K9: Février | L9: 0.92
A10: Janvier | B10: 1 | C10: IDF | D10: Services | E10: 127 | F10: 19343.03 | G10: 7491.2 | H10: 4060.89 | I10: 1513.87 | K10: Mars | L10: 1
A11: Janvier | B11: 1 | C11: Nord | D11: Services | E11: 83 | F11: 12482.92 | G11: 4984.55 | H11: 2633.98 | I11: 1025.24 | K11: Avril | L11: 1.02
A12: Janvier | B12: 1 | C12: Sud | D12: Services | E12: 73 | F12: 11058.05 | G12: 4172.83 | H12: 2294.82 | I12: 870.81 | K12: Mai | L12: 1.03
A13: Janvier | B13: 1 | C13: Export | D13: Services | E13: 54 | F13: 8145.76 | G13: 3066.63 | H13: 1659.33 | I13: 634.67 | K13: Juin | L13: 1.05
A14: Février | B14: 2 | C14: IDF | D14: composants | E14: 1890 | F14: 85716.33 | G14: 33373.22 | H14: 18073.85 | I14: 6960.24 | K14: Juillet | L14: 0.95
A15: Février | B15: 2 | C15: Nord | D15: composants | E15: 1172 | F15: 52140.77 | G15: 21921.77 | H15: 11315.83 | I15: 4049.73 | K15: Août | L15: 0.55
A16: Février | B16: 2 | C16: Sud | D16: composants | E16: 1074 | F16: 48730.45 | G16: 19844.7 | H16: 10559.45 | I16: 3891.14 | K16: Septembre | L16: 1
A17: Février | B17: 2 | C17: Export | D17: composants | E17: 772 | F17: 34510.7 | G17: 14194.29 | H17: 7664.71 | I17: 2827.4 | K17: Octobre | L17: 1.08
A18: Février | B18: 2 | C18: IDF | D18: Equipements | E18: 215 | F18: 67437.81 | G18: 29711.66 | H18: 15586.83 | I18: 5471.91 | K18: Novembre | L18: 1.12
A19: Février | B19: 2 | C19: Nord | D19: Equipements | E19: 133 | F19: 42125.71 | G19: 17930.6 | H19: 9908.01 | I19: 3463.81 | K19: Décembre | L19: 1.2
A20: Février | B20: 2 | C20: Sud | D20: Equipements | E20: 126 | F20: 39779.4 | G20: 16982.44 | H20: 9383.3 | I20: 3213.78
A21: Février | B21: 2 | C21: Export | D21: Equipements | E21: 93 | F21: 30231.47 | G21: 12805.6 | H21: 6788.3 | I21: 2388.56
A22: Février | B22: 2 | C22: IDF | D22: Services | E22: 138 | F22: 20720.46 | G22: 7952.2 | H22: 4239.88 | I22: 1664.92 | K22: Région | L22: Poids
A23: Février | B23: 2 | C23: Nord | D23: Services | E23: 81 | F23: 12050.4 | G23: 4698.61 | H23: 2509.09 | I23: 946.71 | K23: IDF | L23: 0.38
A24: Février | B24: 2 | C24: Sud | D24: Services | E24: 80 | F24: 12239.52 | G24: 4629.77 | H24: 2495.28 | I24: 1000.28 | K24: Nord | L24: 0.24
A25: Février | B25: 2 | C25: Export | D25: Services | E25: 55 | F25: 8155.99 | G25: 3172.09 | H25: 1699.97 | I25: 651.41 | K25: Sud | L25: 0.22
A26: Mars | B26: 3 | C26: IDF | D26: composants | E26: 1982 | F26: 89317.09 | G26: 36009.36 | H26: 19363.45 | I26: 7280.94 | K26: Export | L26: 0.16
A27: Mars | B27: 3 | C27: Nord | D27: composants | E27: 1293 | F27: 58378.05 | G27: 23384.31 | H27: 12685.9 | I27: 4801.53
A28: Mars | B28: 3 | C28: Sud | D28: composants | E28: 1144 | F28: 51098.14 | G28: 21232.24 | H28: 10930.93 | I28: 4048.46
A29: Mars | B29: 3 | C29: Export | D29: composants | E29: 804 | F29: 36058.75 | G29: 14853.24 | H29: 7735.52 | I29: 2938.91
A30: Mars | B30: 3 | C30: IDF | D30: Equipements | E30: 241 | F30: 78073.71 | G30: 32817.38 | H30: 18022.72 | I30: 6182.2
A31: Mars | B31: 3 | C31: Nord | D31: Equipements | E31: 150 | F31: 47431.52 | G31: 20287.16 | H31: 11094.84 | I31: 3905.01
A32: Mars | B32: 3 | C32: Sud | D32: Equipements | E32: 136 | F32: 43666.67 | G32: 18144.49 | H32: 10100.37 | I32: 3399.27
A33: Mars | B33: 3 | C33: Export | D33: Equipements | E33: 95 | F33: 30613.86 | G33: 12862.3 | H33: 6906.15 | I33: 2501.07
A34: Mars | B34: 3 | C34: IDF | D34: Services | E34: 146 | F34: 21760.19 | G34: 8495.23 | H34: 4669.79 | I34: 1738.81
A35: Mars | B35: 3 | C35: Nord | D35: Services | E35: 88 | F35: 13402.18 | G35: 5192.96 | H35: 2735.39 | I35: 1084.27
A36: Mars | B36: 3 | C36: Sud | D36: Services | E36: 84 | F36: 12683.14 | G36: 5039.3 | H36: 2644.41 | I36: 989.1
A37: Mars | B37: 3 | C37: Export | D37: Services | E37: 60 | F37: 8938.39 | G37: 3507.11 | H37: 1848.55 | I37: 710.4
A38: Avril | B38: 4 | C38: IDF | D38: composants | E38: 2054 | F38: 92222.33 | G38: 40112.91 | H38: 20590.2 | I38: 7413.18
... A145: Décembre | B145: 12 | C145: Export | D145: Services | E145: 74 | F145: 11176.65 | G145: 4219.55 | H145: 2279.26 | I145: 907.13

Sheet Consolide
A1: Mois | B1: N° mois | C1: Région | D1: Produit | E1: Type | F1: Volume | G1: CA | H1: Cout_Matières | I1: Cout_MO | J1: Charges fixes
A2: =BUDGET!A2 -> Janvier | B2: {=_xlfn.SWITCH(TRIM(A2),"Janvier",1,"Février",2,"Mars",3,"Avril",4,"Mai",5,"Juin",6,"Juillet",7,"Août",8,"Septembre",9,"Octobre",10,"Novembre",11,"Décembre",12,NA())} -> 1 | C2: =BUDGET!C2 -> IDF | D2: =BUDGET!D2 -> composants | E2: budget | F2: =BUDGET!E2 -> 1778 | G2: =BUDGET!F2 -> 80010 | H2: =BUDGET!G2 -> 32359.6 | I2: =BUDGET!H2 -> 17424.4 | J2: =BUDGET!I2 -> 6400.8
A3: =BUDGET!A3 -> Janvier | B3: {=_xlfn.SWITCH(TRIM(A3),"Janvier",1,"Février",2,"Mars",3,"Avril",4,"Mai",5,"Juin",6,"Juillet",7,"Août",8,"Septembre",9,"Octobre",10,"Novembre",11,"Décembre",12,NA())} -> 1 | C3: =BUDGET!C3 -> Nord | D3: =BUDGET!D3 -> composants | E3: budget | F3: =BUDGET!E3 -> 1123 | G3: =BUDGET!F3 -> 50535 | H3: =BUDGET!G3 -> 20438.6 | I3: =BUDGET!H3 -> 11005.4 | J3: =BUDGET!I3 -> 4042.8
A4: =BUDGET!A4 -> Janvier | B4: {=_xlfn.SWITCH(TRIM(A4),"Janvier",1,"Février",2,"Mars",3,"Avril",4,"Mai",5,"Juin",6,"Juillet",7,"Août",8,"Septembre",9,"Octobre",10,"Novembre",11,"Décembre",12,NA())} -> 1 | C4: =BUDGET!C4 -> Sud | D4: =BUDGET!D4 -> composants | E4: budget | F4: =BUDGET!E4 -> 1030 | G4: =BUDGET!F4 -> 46350 | H4: =BUDGET!G4 -> 18746 | I4: =BUDGET!H4 -> 10094 | J4: =BUDGET!I4 -> 3708
A5: =BUDGET!A5 -> Janvier | B5: {=_xlfn.SWITCH(TRIM(A5),"Janvier",1,"Février",2,"Mars",3,"Avril",4,"Mai",5,"Juin",6,"Juillet",7,"Août",8,"Septembre",9,"Octobre",10,"Novembre",11,"Décembre",12,NA())} -> 1 | C5: =BUDGET!C5 -> Export | D5: =BUDGET!D5 -> composants | E5: budget | F5: =BUDGET!E5 -> 749 | G5: =BUDGET!F5 -> 33705 | H5: =BUDGET!G5 -> 13631.8 | I5: =BUDGET!H5 -> 7340.2 | J5: =BUDGET!I5 -> 2696.4
A6: =BUDGET!A6 -> Janvier | B6: {=_xlfn.SWITCH(TRIM(A6),"Janvier",1,"Février",2,"Mars",3,"Avril",4,"Mai",5,"Juin",6,"Juillet",7,"Août",8,"Septembre",9,"Octobre",10,"Novembre",11,"Décembre",12,NA())} -> 1 | C6: =BUDGET!C6 -> IDF | D6: =BUDGET!D6 -> Equipements | E6: budget | F6: =BUDGET!E6 -> 212 | G6: =BUDGET!F6 -> 67840 | H6: =BUDGET!G6 -> 28938 | I6: =BUDGET!H6 -> 15582 | J6: =BUDGET!I6 -> 5427.2
A7: =BUDGET!A7 -> Janvier | B7: {=_xlfn.SWITCH(TRIM(A7),"Janvier",1,"Février",2,"Mars",3,"Avril",4,"Mai",5,"Juin",6,"Juillet",7,"Août",8,"Septembre",9,"Octobre",10,"Novembre",11,"Décembre",12,NA())} -> 1 | C7: =BUDGET!C7 -> Nord | D7: =BUDGET!D7 -> Equipements | E7: budget | F7: =BUDGET!E7 -> 134 | G7: =BUDGET!F7 -> 42880 | H7: =BUDGET!G7 -> 18291 | I7: =BUDGET!H7 -> 9849 | J7: =BUDGET!I7 -> 3430.4
A8: =BUDGET!A8 -> Janvier | B8: {=_xlfn.SWITCH(TRIM(A8),"Janvier",1,"Février",2,"Mars",3,"Avril",4,"Mai",5,"Juin",6,"Juillet",7,"Août",8,"Septembre",9,"Octobre",10,"Novembre",11,"Décembre",12,NA())} -> 1 | C8: =BUDGET!C8 -> Sud | D8: =BUDGET!D8 -> Equipements | E8: budget | F8: =BUDGET!E8 -> 123 | G8: =BUDGET!F8 -> 39360 | H8: =BUDGET!G8 -> 16789.5 | I8: =BUDGET!H8 -> 9040.5 | J8: =BUDGET!I8 -> 3148.8
A9: =BUDGET!A9 -> Janvier | B9: {=_xlfn.SWITCH(TRIM(A9),"Janvier",1,"Février",2,"Mars",3,"Avril",4,"Mai",5,"Juin",6,"Juillet",7,"Août",8,"Septembre",9,"Octobre",10,"Novembre",11,"Décembre",12,NA())} -> 1 | C9: =BUDGET!C9 -> Export | D9: =BUDGET!D9 -> Equipements | E9: budget | F9: =BUDGET!E9 -> 89 | G9: =BUDGET!F9 -> 28480 | H9: =BUDGET!G9 -> 12148.5 | I9: =BUDGET!H9 -> 6541.5 | J9: =BUDGET!I9 -> 2278.4
A10: =BUDGET!A10 -> Janvier | B10: {=_xlfn.SWITCH(TRIM(A10),"Janvier",1,"Février",2,"Mars",3,"Avril",4,"Mai",5,"Juin",6,"Juillet",7,"Août",8,"Septembre",9,"Octobre",10,"Novembre",11,"Décembre",12,NA())} -> 1 | C10: =BUDGET!C10 -> IDF | D10: =BUDGET!D10 -> Services | E10: budget | F10: =BUDGET!E10 -> 130 | G10: =BUDGET!F10 -> 19500 | H10: =BUDGET!G10 -> 7605 | I10: =BUDGET!H10 -> 4095 | J10: =BUDGET!I10 -> 1560
A11: =BUDGET!A11 -> Janvier | B11: {=_xlfn.SWITCH(TRIM(A11),"Janvier",1,"Février",2,"Mars",3,"Avril",4,"Mai",5,"Juin",6,"Juillet",7,"Août",8,"Septembre",9,"Octobre",10,"Novembre",11,"Décembre",12,NA())} -> 1 | C11: =BUDGET!C11 -> Nord | D11: =BUDGET!D11 -> Services | E11: budget | F11: =BUDGET!E11 -> 82 | G11: =BUDGET!F11 -> 12300 | H11: =BUDGET!G11 -> 4797 | I11: =BUDGET!H11 -> 2583 | J11: =BUDGET!I11 -> 984
A12: =BUDGET!A12 -> Janvier | B12: {=_xlfn.SWITCH(TRIM(A12),"Janvier",1,"Février",2,"Mars",3,"Avril",4,"Mai",5,"Juin",6,"Juillet",7,"Août",8,"Septembre",9,"Octobre",10,"Novembre",11,"Décembre",12,NA())} -> 1 | C12: =BUDGET!C12 -> Sud | D12: =BUDGET!D12 -> Services | E12: budget | F12: =BUDGET!E12 -> 75 | G12: =BUDGET!F12 -> 11250 | H12: =BUDGET!G12 -> 4387.5 | I12: =BUDGET!H12 -> 2362.5 | J12: =BUDGET!I12 -> 900
A13: =BUDGET!A13 -> Janvier | B13: {=_xlfn.SWITCH(TRIM(A13),"Janvier",1,"Février",2,"Mars",3,"Avril",4,"Mai",5,"Juin",6,"Juillet",7,"Août",8,"Septembre",9,"Octobre",10,"Novembre",11,"Décembre",12,NA())} -> 1 | C13: =BUDGET!C13 -> Export | D13: =BUDGET!D13 -> Services | E13: budget | F13: =BUDGET!E13 -> 55 | G13: =BUDGET!F13 -> 8250 | H13: =BUDGET!G13 -> 3217.5 | I13: =BUDGET!H13 -> 1732.5 | J13: =BUDGET!I13 -> 660
... A145: =BUDGET!A145 -> Décembre | B145: {=_xlfn.SWITCH(TRIM(A145),"Janvier",1,"Février",2,"Mars",3,"Avril",4,"Mai",5,"Juin",6,"Juillet",7,"Août",8,"Septembre",9,"Octobre",10,"Novembre",11,"Décembre",12,NA())} -> 12 | C145: =BUDGET!C145 -> Export | D145: =BUDGET!D145 -> Services | E145: budget | F145: =BUDGET!E145 -> 73 | G145: =BUDGET!F145 -> 10950 | H145: =BUDGET!G145 -> 4270.5 | I145: =BUDGET!H145 -> 2299.5 | J145: =BUDGET!I145 -> 876
A146: =REEL!A2 -> Janvier | B146: {=_xlfn.SWITCH(TRIM(A146),"Janvier",1,"Février",2,"Mars",3,"Avril",4,"Mai",5,"Juin",6,"Juillet",7,"Août",8,"Septembre",9,"Octobre",10,"Novembre",11,"Décembre",12,NA())} -> 1 | C146: =REEL!C2 -> IDF | D146: =REEL!D2 -> composants | E146: réel | F146: =REEL!E2 -> 1804 | G146: =REEL!F2 -> 79791.69 | H146: =REEL!G2 -> 32702.51 | I146: =REEL!H2 -> 18043.73 | J146: =REEL!I2 -> 6315.18
A147: =REEL!A3 -> Janvier | B147: {=_xlfn.SWITCH(TRIM(A147),"Janvier",1,"Février",2,"Mars",3,"Avril",4,"Mai",5,"Juin",6,"Juillet",7,"Août",8,"Septembre",9,"Octobre",10,"Novembre",11,"Décembre",12,NA())} -> 1 | C147: =REEL!C3 -> Nord | D147: =REEL!D3 -> composants | E147: réel | F147: =REEL!E3 -> 1123 | G147: =REEL!F3 -> 50291.38 | H147: =REEL!G3 -> 20096.43 | I147: =REEL!H3 -> 11240.93 | J147: =REEL!I3 -> 3973.54
A148: =REEL!A4 -> Janvier | B148: {=_xlfn.SWITCH(TRIM(A148),"Janvier",1,"Février",2,"Mars",3,"Avril",4,"Mai",5,"Juin",6,"Juillet",7,"Août",8,"Septembre",9,"Octobre",10,"Novembre",11,"Décembre",12,NA())} -> 1 | C148: =REEL!C4 -> Sud | D148: =REEL!D4 -> composants | E148: réel | F148: =REEL!E4 -> 1011 | G148: =REEL!F4 -> 46357.53 | H148: =REEL!G4 -> 17992.31 | I148: =REEL!H4 -> 9946.54 | J148: =REEL!I4 -> 3652.28
A149: =REEL!A5 -> Janvier | B149: {=_xlfn.SWITCH(TRIM(A149),"Janvier",1,"Février",2,"Mars",3,"Avril",4,"Mai",5,"Juin",6,"Juillet",7,"Août",8,"Septembre",9,"Octobre",10,"Novembre",11,"Décembre",12,NA())} -> 1 | C149: =REEL!C5 -> Export | D149: =REEL!D5 -> composants | E149: réel | F149: =REEL!E5 -> 729 | G149: =REEL!F5 -> 32813.6 | H149: =REEL!G5 -> 12926.24 | I149: =REEL!H5 -> 7153.37 | J149: =REEL!I5 -> 2595.01
A150: =REEL!A6 -> Janvier | B150: {=_xlfn.SWITCH(TRIM(A150),"Janvier",1,"Février",2,"Mars",3,"Avril",4,"Mai",5,"Juin",6,"Juillet",7,"Août",8,"Septembre",9,"Octobre",10,"Novembre",11,"Décembre",12,NA())} -> 1 | C150: =REEL!C6 -> IDF | D150: =REEL!D6 -> Equipements | E150: réel | F150: =REEL!E6 -> 219 | G150: =REEL!F6 -> 70576.98 | H150: =REEL!G6 -> 29813.15 | I150: =REEL!H6 -> 16233.12 | J150: =REEL!I6 -> 5644.62
A151: =REEL!A7 -> Janvier | B151: {=_xlfn.SWITCH(TRIM(A151),"Janvier",1,"Février",2,"Mars",3,"Avril",4,"Mai",5,"Juin",6,"Juillet",7,"Août",8,"Septembre",9,"Octobre",10,"Novembre",11,"Décembre",12,NA())} -> 1 | C151: =REEL!C7 -> Nord | D151: =REEL!D7 -> Equipements | E151: réel | F151: =REEL!E7 -> 133 | G151: =REEL!F7 -> 42465.23 | H151: =REEL!G7 -> 17717.96 | I151: =REEL!H7 -> 9906.25 | J151: =REEL!I7 -> 3424.2
A152: =REEL!A8 -> Janvier | B152: {=_xlfn.SWITCH(TRIM(A152),"Janvier",1,"Février",2,"Mars",3,"Avril",4,"Mai",5,"Juin",6,"Juillet",7,"Août",8,"Septembre",9,"Octobre",10,"Novembre",11,"Décembre",12,NA())} -> 1 | C152: =REEL!C8 -> Sud | D152: =REEL!D8 -> Equipements | E152: réel | F152: =REEL!E8 -> 127 | G152: =REEL!F8 -> 40550.99 | H152: =REEL!G8 -> 17603.09 | I152: =REEL!H8 -> 9152.54 | J152: =REEL!I8 -> 3205.13
A153: =REEL!A9 -> Janvier | B153: {=_xlfn.SWITCH(TRIM(A153),"Janvier",1,"Février",2,"Mars",3,"Avril",4,"Mai",5,"Juin",6,"Juillet",7,"Août",8,"Septembre",9,"Octobre",10,"Novembre",11,"Décembre",12,NA())} -> 1 | C153: =REEL!C9 -> Export | D153: =REEL!D9 -> Equipements | E153: réel | F153: =REEL!E9 -> 88 | G153: =REEL!F9 -> 27947.03 | H153: =REEL!G9 -> 11991.17 | I153: =REEL!H9 -> 6442.79 | J153: =REEL!I9 -> 2295.97
A154: =REEL!A10 -> Janvier | B154: {=_xlfn.SWITCH(TRIM(A154),"Janvier",1,"Février",2,"Mars",3,"Avril",4,"Mai",5,"Juin",6,"Juillet",7,"Août",8,"Septembre",9,"Octobre",10,"Novembre",11,"Décembre",12,NA())} -> 1 | C154: =REEL!C10 -> IDF | D154: =REEL!D10 -> Services | E154: réel | F154: =REEL!E10 -> 127 | G154: =REEL!F10 -> 19343.03 | H154: =REEL!G10 -> 7491.2 | I154: =REEL!H10 -> 4060.89 | J154: =REEL!I10 -> 1513.87
A155: =REEL!A11 -> Janvier | B155: {=_xlfn.SWITCH(TRIM(A155),"Janvier",1,"Février",2,"Mars",3,"Avril",4,"Mai",5,"Juin",6,"Juillet",7,"Août",8,"Septembre",9,"Octobre",10,"Novembre",11,"Décembre",12,NA())} -> 1 | C155: =REEL!C11 -> Nord | D155: =REEL!D11 -> Services | E155: réel | F155: =REEL!E11 -> 83 | G155: =REEL!F11 -> 12482.92 | H155: =REEL!G11 -> 4984.55 | I155: =REEL!H11 -> 2633.98 | J155: =REEL!I11 -> 1025.24
A156: =REEL!A12 -> Janvier | B156: {=_xlfn.SWITCH(TRIM(A156),"Janvier",1,"Février",2,"Mars",3,"Avril",4,"Mai",5,"Juin",6,"Juillet",7,"Août",8,"Septembre",9,"Octobre",10,"Novembre",11,"Décembre",12,NA())} -> 1 | C156: =REEL!C12 -> Sud | D156: =REEL!D12 -> Services | E156: réel | F156: =REEL!E12 -> 73 | G156: =REEL!F12 -> 11058.05 | H156: =REEL!G12 -> 4172.83 | I156: =REEL!H12 -> 2294.82 | J156: =REEL!I12 -> 870.81
A157: =REEL!A13 -> Janvier | B157: {=_xlfn.SWITCH(TRIM(A157),"Janvier",1,"Février",2,"Mars",3,"Avril",4,"Mai",5,"Juin",6,"Juillet",7,"Août",8,"Septembre",9,"Octobre",10,"Novembre",11,"Décembre",12,NA())} -> 1 | C157: =REEL!C13 -> Export | D157: =REEL!D13 -> Services | E157: réel | F157: =REEL!E13 -> 54 | G157: =REEL!F13 -> 8145.76 | H157: =REEL!G13 -> 3066.63 | I157: =REEL!H13 -> 1659.33 | J157: =REEL!I13 -> 634.67
... A289: =REEL!A145 -> Décembre | B289: {=_xlfn.SWITCH(TRIM(A289),"Janvier",1,"Février",2,"Mars",3,"Avril",4,"Mai",5,"Juin",6,"Juillet",7,"Août",8,"Septembre",9,"Octobre",10,"Novembre",11,"Décembre",12,NA())} -> 12 | C289: =REEL!C145 -> Export | D289: =REEL!D145 -> Services | E289: réel | F289: =REEL!E145 -> 74 | G289: =REEL!F145 -> 11176.65 | H289: =REEL!G145 -> 4219.55 | I289: =REEL!H145 -> 2279.26 | J289: =REEL!I145 -> 907.13

Sheet Dashboard
A1: Région | B1: (All)
B3: Column Labels
B4: Total du CA | E4: Ordre mois
A5: Row Labels | B5: budget | C5: réel | D5: Ecart | E5: budget | F5: réel | G5: Ecart | I5: Ecart %
A6: Janvier | B6: 440460 | C6: 441824.19 | D6: 1364.19 | E6: 12 | F6: 12 | G6: 0 | I6: =IFERROR(D6/B6,0) -> 0.0030971938
A7: Février | B7: 450135 | C7: 453839.01 | D7: 3704.01 | E7: 24 | F7: 24 | G7: 0 | I7: =IFERROR(D7/B7,0) -> 0.0082286647
A8: Mars | B8: 489400 | C8: 491421.69 | D8: 2021.69 | E8: 36 | F8: 36 | G8: 0 | I8: =IFERROR(D8/B8,0) -> 0.0041309563
A9: Avril | B9: 499015 | C9: 504318.51 | D9: 5303.51 | E9: 48 | F9: 48 | G9: 0 | I9: =IFERROR(D9/B9,0) -> 0.010627957
A10: Mai | B10: 503935 | C10: 504154.63 | D10: 219.63 | E10: 60 | F10: 60 | G10: 0 | I10: =IFERROR(D10/B10,0) -> 0.00043583002
A11: Juin | B11: 513700 | C11: 515693.36 | D11: 1993.36 | E11: 72 | F11: 72 | G11: 0 | I11: =IFERROR(D11/B11,0) -> 0.0038803971
A12: Juillet | B12: 464930 | C12: 454596.31 | D12: -10333.69 | E12: 84 | F12: 84 | G12: 0 | I12: =IFERROR(D12/B12,0) -> -0.022226335
A13: Août | B13: 269340 | C13: 272205.67 | D13: 2865.67 | E13: 96 | F13: 96 | G13: 0 | I13: =IFERROR(D13/B13,0) -> 0.010639601
A14: Septembre | B14: 489400 | C14: 491601.4 | D14: 2201.4 | E14: 108 | F14: 108 | G14: 0 | I14: =IFERROR(D14/B14,0) -> 0.004498161
A15: Octobre | B15: 528345 | C15: 525185.98 | D15: -3159.02 | E15: 120 | F15: 120 | G15: 0 | I15: =IFERROR(D15/B15,0) -> -0.0059790856
A16: Novembre | B16: 548380 | C16: 547950.19 | D16: -429.81 | E16: 132 | F16: 132 | G16: 0 | I16: =IFERROR(D16/B16,0) -> -0.00078378132
A17: Décembre | B17: 587450 | C17: 586091.94 | D17: -1358.06 | E17: 144 | F17: 144 | G17: 0 | I17: =IFERROR(D17/B17,0) -> -0.0023117882
A18: Grand Total | B18: 5784490 | C18: 5788882.9 | D18: 4392.88 | E18: 936 | F18: 936 | G18: 0 | I18: =IFERROR(D18/B18,0) -> 0.00075942391

Sheet Dashboard_Coût
A1: Produit | B1: Equipements
A2: Région | B2: (All)
B4: Column Labels
B5: budget | C5: budget | D5: Ecart | E5: Ecart | F5: réel | G5: réel | I5: Ecart %
A6: Row Labels | B6: Total des Coût_Matières | C6: Ordre mois | D6: Total des Coût_Matières | E6: Ordre mois | F6: Total des Coût_Matières | G6: Ordre mois
A7: Janvier | B7: 76167 | C7: 4 | D7: 958.37 | E7: 0 | F7: 77125.37 | G7: 4 | I7: =IFERROR(D7/B7,0) -> 0.012582483
A8: Février | B8: 77805 | C8: 8 | D8: -374.7 | E8: 0 | F8: 77430.3 | G8: 8 | I8: =IFERROR(D8/B8,0) -> -0.0048158859
A9: Mars | B9: 84630 | C9: 12 | D9: -518.67 | E9: 0 | F9: 84111.33 | G9: 12 | I9: =IFERROR(D9/B9,0) -> -0.0061286778
A10: Avril | B10: 86268 | C10: 16 | D10: -424.67 | E10: 0 | F10: 85843.33 | G10: 16 | I10: =IFERROR(D10/B10,0) -> -0.0049226828
A11: Mai | B11: 87087 | C11: 20 | D11: -874.13 | E11: 0 | F11: 86212.87 | G11: 20 | I11: =IFERROR(D11/B11,0) -> -0.010037434
A12: Juin | B12: 88725 | C12: 24 | D12: 166.46 | E12: 0 | F12: 88891.46 | G12: 24 | I12: =IFERROR(D12/B12,0) -> 0.0018761341
A13: Juillet | B13: 80398.5 | C13: 28 | D13: -1579.35 | E13: 0 | F13: 78819.15 | G13: 28 | I13: =IFERROR(D13/B13,0) -> -0.019644023
A14: Août | B14: 46683 | C14: 32 | D14: -476.7 | E14: 0 | F14: 46206.3 | G14: 32 | I14: =IFERROR(D14/B14,0) -> -0.010211426
A15: Septembre | B15: 84630 | C15: 36 | D15: -829.39 | E15: 0 | F15: 83800.61 | G15: 36 | I15: =IFERROR(D15/B15,0) -> -0.0098001891
A16: Octobre | B16: 91318.5 | C16: 40 | D16: 1589.52 | E16: 0 | F16: 92908.02 | G16: 40 | I16: =IFERROR(D16/B16,0) -> 0.017406331
A17: Novembre | B17: 94867.5 | C17: 44 | D17: 77.85 | E17: 0 | F17: 94945.35 | G17: 44 | I17: =IFERROR(D17/B17,0) -> 0.00082061823
A18: Décembre | B18: 101692.5 | C18: 48 | D18: 170.4 | E18: 0 | F18: 101862.9 | G18: 48 | I18: =IFERROR(D18/B18,0) -> 0.0016756398
A19: Grand Total | B19: 1000272 | C19: 312 | D19: -2115.01 | E19: 0 | F19: 998156.99 | G19: 312

Sheet ANALYSE_VPM
A1: Produit | B1: Volume_budget | C1: Volume_reel | D1: Prix_Budget | E1: Prix_Reel | F1: Effet_Volume | G1: Effet_Prix | H1: Ecart_Total_CA | I1: Verification | J1: Volume_Total_Budget | K1: Volume_Total_Reel | L1: Part_Budget | M1: Part_Reel | N1: Effet_Mix | O1: Prix_Moyen_Budget_Pondere
A2: composants | B2: =SUMIFS(Consolide!$F$2:$F$289,Consolide!$D$2:$D$289,$A2,Consolide!$E$2:$E$289,"Budget") -> 61464 | C2: =SUMIFS(Consolide!$F$2:$F$289,Consolide!$D$2:$D$289,$A2,Consolide!$E$2:$E$289,"Réel") -> 61920 | D2: =SUMIFS(Consolide!$G$2:$G$289,Consolide!$D$2:$D$289,$A2,Consolide!$E$2:$E$289,"Budget")/B2 -> 45 | E2: =SUMIFS(Consolide!$G$2:$G$289,Consolide!$D$2:$D$289,$A2,Consolide!$E$2:$E$289,"Réel")/C2 -> 44.923218 | F2: =(C2-B2)*D2 -> 20520 | G2: =(E2-D2)*C2 -> -4754.34 | H2: =C2*E2-B2*D2 -> 15765.66 | I2: =ROUND(F2+G2-H2,2) -> 0 | J2: =SUM($B$2:$B$4) -> 73283 | K2: =SUM($C$2:$C$4) -> 73732 | L2: =B2/J2 -> 0.83872112 | M2: =C2/K2 -> 0.83979819 | N2: =(M2-L2)*K2*D2 -> 3573.6397 | O2: =SUMPRODUCT($B$2:$B$4,$D$2:$D$4)/J2 -> 78.933586
A3: Equipements | B3: =SUMIFS(Consolide!$F$2:$F$289,Consolide!$D$2:$D$289,$A3,Consolide!$E$2:$E$289,"Budget") -> 7328 | C3: =SUMIFS(Consolide!$F$2:$F$289,Consolide!$D$2:$D$289,$A3,Consolide!$E$2:$E$289,"Réel") -> 7346 | D3: =SUMIFS(Consolide!$G$2:$G$289,Consolide!$D$2:$D$289,$A3,Consolide!$E$2:$E$289,"Budget")/B3 -> 320 | E3: =SUMIFS(Consolide!$G$2:$G$289,Consolide!$D$2:$D$289,$A3,Consolide!$E$2:$E$289,"Réel")/C3 -> 318.18561 | F3: =(C3-B3)*D3 -> 5760 | G3: =(E3-D3)*C3 -> -13328.53 | H3: =C3*E3-B3*D3 -> -7568.53 | I3: =ROUND(F3+G3-H3,2) -> 0 | J3: =SUM($B$2:$B$4) -> 73283 | K3: =SUM($C$2:$C$4) -> 73732 | L3: =B3/J3 -> 0.099995906 | M3: =C3/K3 -> 0.099631096 | N3: =(M3-L3)*K3*D3 -> -8607.4118 | O3: =(K2-J2)*O2 -> 35441.18
A4: Services | B4: =SUMIFS(Consolide!$F$2:$F$289,Consolide!$D$2:$D$289,$A4,Consolide!$E$2:$E$289,"Budget") -> 4491 | C4: =SUMIFS(Consolide!$F$2:$F$289,Consolide!$D$2:$D$289,$A4,Consolide!$E$2:$E$289,"Réel") -> 4466 | D4: =SUMIFS(Consolide!$G$2:$G$289,Consolide!$D$2:$D$289,$A4,Consolide!$E$2:$E$289,"Budget")/B4 -> 150 | E4: =SUMIFS(Consolide!$G$2:$G$289,Consolide!$D$2:$D$289,$A4,Consolide!$E$2:$E$289,"Réel")/C4 -> 149.98785 | F4: =(C4-B4)*D4 -> -3750 | G4: =(E4-D4)*C4 -> -54.25 | H4: =C4*E4-B4*D4 -> -3804.25 | I4: =ROUND(F4+G4-H4,2) -> 0 | J4: =SUM($B$2:$B$4) -> 73283 | K4: =SUM($C$2:$C$4) -> 73732 | L4: =B4/J4 -> 0.061282971 | M4: =C4/K4 -> 0.060570716 | N4: =(M4-L4)*K4*D4 -> -7877.4081 | O4: =O3+SUM($N$2:$N$4)+SUM($G$2:$G$4) -> 4392.88
O5: =ROUND(O4-SUM($H$2:$H$4),2) -> 0

Sheet ANALYSE_MARGE
A1: Produit | B1: CA_Budget | C1: Couts_Budget | D1: Marge_Budget | E1: Taux_Budget | F1: CA_Reel | G1: Couts_Reel | H1: Marge_Reel | I1: Taux_Reel | J1: Ecart_Marge_€ | K1: Ecart_Taux_pts
A2: composants | B2: =SUMIFS(Consolide!$G$2:$G$289,Consolide!$D$2:$D$289,$A2,Consolide!$E$2:$E$289,"Budget") -> 2765880 | C2: =SUMIFS(Consolide!$H$2:$H$289,Consolide!$D$2:$D$289,$A2,Consolide!$E$2:$E$289,"Budget")+SUMIFS(Consolide!$I$2:$I$289,Consolide!$D$2:$D$289,$A2,Consolide!$E$2:$E$289,"Budget")+SUMIFS(Consolide!$J$2:$J$289,Consolide!$D$2:$D$289,$A2,Consolide!$E$2:$E$289,"Budget") -> 1942262.4 | D2: =B2-C2 -> 823617.6 | E2: =D2/B2 -> 0.29777778 | F2: =SUMIFS(Consolide!$G$2:$G$289,Consolide!$D$2:$D$289,$A2,Consolide!$E$2:$E$289,"Réel") -> 2781645.7 | G2: =SUMIFS(Consolide!$H$2:$H$289,Consolide!$D$2:$D$289,$A2,Consolide!$E$2:$E$289,"Réel")+SUMIFS(Consolide!$I$2:$I$289,Consolide!$D$2:$D$289,$A2,Consolide!$E$2:$E$289,"Réel")+SUMIFS(Consolide!$J$2:$J$289,Consolide!$D$2:$D$289,$A2,Consolide!$E$2:$E$289,"Réel") -> 1986565 | H2: =F2-G2 -> 795080.62 | I2: =H2/F2 -> 0.28583102 | J2: =H2-D2 -> -28536.98 | K2: =I2-E2 -> -0.011946756
A3: Equipements | B3: =SUMIFS(Consolide!$G$2:$G$289,Consolide!$D$2:$D$289,$A3,Consolide!$E$2:$E$289,"Budget") -> 2344960 | C3: =SUMIFS(Consolide!$H$2:$H$289,Consolide!$D$2:$D$289,$A3,Consolide!$E$2:$E$289,"Budget")+SUMIFS(Consolide!$I$2:$I$289,Consolide!$D$2:$D$289,$A3,Consolide!$E$2:$E$289,"Budget")+SUMIFS(Consolide!$J$2:$J$289,Consolide!$D$2:$D$289,$A3,Consolide!$E$2:$E$289,"Budget") -> 1726476.8 | D3: =B3-C3 -> 618483.2 | E3: =D3/B3 -> 0.26375 | F3: =SUMIFS(Consolide!$G$2:$G$289,Consolide!$D$2:$D$289,$A3,Consolide!$E$2:$E$289,"Réel") -> 2337391.5 | G3: =SUMIFS(Consolide!$H$2:$H$289,Consolide!$D$2:$D$289,$A3,Consolide!$E$2:$E$289,"Réel")+SUMIFS(Consolide!$I$2:$I$289,Consolide!$D$2:$D$289,$A3,Consolide!$E$2:$E$289,"Réel")+SUMIFS(Consolide!$J$2:$J$289,Consolide!$D$2:$D$289,$A3,Consolide!$E$2:$E$289,"Réel") -> 1725124.6 | H3: =F3-G3 -> 612266.91 | I3: =H3/F3 -> 0.26194453 | J3: =H3-D3 -> -6216.29 | K3: =I3-E3 -> -0.00180547
A4: Services | B4: =SUMIFS(Consolide!$G$2:$G$289,Consolide!$D$2:$D$289,$A4,Consolide!$E$2:$E$289,"Budget") -> 673650 | C4: =SUMIFS(Consolide!$H$2:$H$289,Consolide!$D$2:$D$289,$A4,Consolide!$E$2:$E$289,"Budget")+SUMIFS(Consolide!$I$2:$I$289,Consolide!$D$2:$D$289,$A4,Consolide!$E$2:$E$289,"Budget")+SUMIFS(Consolide!$J$2:$J$289,Consolide!$D$2:$D$289,$A4,Consolide!$E$2:$E$289,"Budget") -> 458082 | D4: =B4-C4 -> 215568 | E4: =D4/B4 -> 0.32 | F4: =SUMIFS(Consolide!$G$2:$G$289,Consolide!$D$2:$D$289,$A4,Consolide!$E$2:$E$289,"Réel") -> 669845.75 | G4: =SUMIFS(Consolide!$H$2:$H$289,Consolide!$D$2:$D$289,$A4,Consolide!$E$2:$E$289,"Réel")+SUMIFS(Consolide!$I$2:$I$289,Consolide!$D$2:$D$289,$A4,Consolide!$E$2:$E$289,"Réel")+SUMIFS(Consolide!$J$2:$J$289,Consolide!$D$2:$D$289,$A4,Consolide!$E$2:$E$289,"Réel") -> 455489.82 | H4: =F4-G4 -> 214355.93 | I4: =H4/F4 -> 0.3200079 | J4: =H4-D4 -> -1212.07 | K4: =I4-E4 -> 7.8973405e-06

Sheet CLIENTS
A1: Client ID | B1: Client Name | C1: Sector | D1: Région | E1: Account Manager | F1: Account size
A2: C001 | B2: Auvergne Automotive Systems | C2: Automobile | D2: Sud | E2: Julien Marchand | F2: Grand Compte
A3: C002 | B3: Rhône Aérostructures | C3: Aéronautique | D3: Sud | E3: Camille Dubois | F3: Grand Compte
A4: C003 | B4: Norbatir Industries | C4: BTP | D4: Nord | E4: Julien Marchand | F4: PME
A5: C004 | B5: ElectroPlast SA | C5: Électroménager | D5: Nord | E5: Sophie Lenoir | F5: PME
A6: C005 | B6: Dauphiné Composants | C6: Automobile | D6: Sud | E6: Camille Dubois | F6: PME
A7: C006 | B7: Nortec Machines | C7: Machines-outils | D7: Nord | E7: Sophie Lenoir | F7: Grand Compte
A8: C007 | B8: Alpina Métallurgie | C8: Métallurgie | D8: Sud | E8: Julien Marchand | F8: PME
A9: C008 | B9: Lyonnaise Câblage | C9: Électronique | D9: Sud | E9: Camille Dubois | F9: PME
A10: C009 | B10: Picardie Assemblage | C10: Automobile | D10: Nord | E10: Sophie Lenoir | F10: PME
A11: C010 | B11: Global Export Partners | C11: Négoce international | D11: Export | E11: Camille Dubois | F11: Grand Compte

Sheet VENTES
A1: N° Commande | B1: Date | C1: ID Client | D1: Région | E1: Produit | F1: Quantité | G1: Prix Unitaire | H1: Chiffre d'Affaires | I1: Coût Unitaire Direct | J1: Coût Direct Total | K1: Marge | L1: Taux de Marge | M1: Nom Client | N1: Secteur | O1: chargé de compte
A2: V001 | B2: 45672 | C2: C001 | D2: Sud | E2: Composants | F2: 120 | G2: 45 | H2: =Tbl_Ventes[[#This Row],[Quantité]]*Tbl_Ventes[[#This Row],[Prix Unitaire]] -> 5400 | I2: 32 | J2: =Tbl_Ventes[[#This Row],[Quantité]]*Tbl_Ventes[[#This Row],[Coût Unitaire Direct]] -> 3840 | K2: =Tbl_Ventes[[#This Row],[Chiffre d''Affaires]]-Tbl_Ventes[[#This Row],[Coût Direct Total]] -> 1560 | L2: =Tbl_Ventes[[#This Row],[Marge]]/Tbl_Ventes[[#This Row],[Chiffre d''Affaires]] -> 0.28888889 | M2: =_xlfn.XLOOKUP(Tbl_Ventes[[#This Row],[ID Client]],Tbl_Clients[Client ID],Tbl_Clients[Client Name]) -> Auvergne Automotive Systems | N2: =_xlfn.XLOOKUP(Tbl_Ventes[[#This Row],[ID Client]],Tbl_Clients[Client ID],Tbl_Clients[Sector]) -> Automobile | O2: =_xlfn.XLOOKUP(Tbl_Ventes[[#This Row],[ID Client]],Tbl_Clients[Client ID],Tbl_Clients[Account Manager]) -> Julien Marchand
A3: V002 | B3: 45675 | C3: C002 | D3: Sud | E3: Modules | F3: 60 | G3: 110 | H3: =Tbl_Ventes[[#This Row],[Quantité]]*Tbl_Ventes[[#This Row],[Prix Unitaire]] -> 6600 | I3: 78 | J3: =Tbl_Ventes[[#This Row],[Quantité]]*Tbl_Ventes[[#This Row],[Coût Unitaire Direct]] -> 4680 | K3: =Tbl_Ventes[[#This Row],[Chiffre d''Affaires]]-Tbl_Ventes[[#This Row],[Coût Direct Total]] -> 1920 | L3: =Tbl_Ventes[[#This Row],[Marge]]/Tbl_Ventes[[#This Row],[Chiffre d''Affaires]] -> 0.29090909 | M3: =_xlfn.XLOOKUP(Tbl_Ventes[[#This Row],[ID Client]],Tbl_Clients[Client ID],Tbl_Clients[Client Name]) -> Rhône Aérostructures | N3: =_xlfn.XLOOKUP(Tbl_Ventes[[#This Row],[ID Client]],Tbl_Clients[Client ID],Tbl_Clients[Sector]) -> Aéronautique | O3: =_xlfn.XLOOKUP(Tbl_Ventes[[#This Row],[ID Client]],Tbl_Clients[Client ID],Tbl_Clients[Account Manager]) -> Camille Dubois
A4: V003 | B4: 45679 | C4: C003 | D4: Nord | E4: Accessoires | F4: 200 | G4: 18 | H4: =Tbl_Ventes[[#This Row],[Quantité]]*Tbl_Ventes[[#This Row],[Prix Unitaire]] -> 3600 | I4: 13 | J4: =Tbl_Ventes[[#This Row],[Quantité]]*Tbl_Ventes[[#This Row],[Coût Unitaire Direct]] -> 2600 | K4: =Tbl_Ventes[[#This Row],[Chiffre d''Affaires]]-Tbl_Ventes[[#This Row],[Coût Direct Total]] -> 1000 | L4: =Tbl_Ventes[[#This Row],[Marge]]/Tbl_Ventes[[#This Row],[Chiffre d''Affaires]] -> 0.27777778 | M4: =_xlfn.XLOOKUP(Tbl_Ventes[[#This Row],[ID Client]],Tbl_Clients[Client ID],Tbl_Clients[Client Name]) -> Norbatir Industries | N4: =_xlfn.XLOOKUP(Tbl_Ventes[[#This Row],[ID Client]],Tbl_Clients[Client ID],Tbl_Clients[Sector]) -> BTP | O4: =_xlfn.XLOOKUP(Tbl_Ventes[[#This Row],[ID Client]],Tbl_Clients[Client ID],Tbl_Clients[Account Manager]) -> Julien Marchand
A5: V004 | B5: 45682 | C5: C004 | D5: Nord | E5: Composants | F5: 90 | G5: 45 | H5: =Tbl_Ventes[[#This Row],[Quantité]]*Tbl_Ventes[[#This Row],[Prix Unitaire]] -> 4050 | I5: 33 | J5: =Tbl_Ventes[[#This Row],[Quantité]]*Tbl_Ventes[[#This Row],[Coût Unitaire Direct]] -> 2970 | K5: =Tbl_Ventes[[#This Row],[Chiffre d''Affaires]]-Tbl_Ventes[[#This Row],[Coût Direct Total]] -> 1080 | L5: =Tbl_Ventes[[#This Row],[Marge]]/Tbl_Ventes[[#This Row],[Chiffre d''Affaires]] -> 0.26666667 | M5: =_xlfn.XLOOKUP(Tbl_Ventes[[#This Row],[ID Client]],Tbl_Clients[Client ID],Tbl_Clients[Client Name]) -> ElectroPlast SA | N5: =_xlfn.XLOOKUP(Tbl_Ventes[[#This Row],[ID Client]],Tbl_Clients[Client ID],Tbl_Clients[Sector]) -> Électroménager | O5: =_xlfn.XLOOKUP(Tbl_Ventes[[#This Row],[ID Client]],Tbl_Clients[Client ID],Tbl_Clients[Account Manager]) -> Sophie Lenoir
A6: V005 | B6: 45685 | C6: C005 | D6: Sud | E6: Modules | F6: 45 | G6: 108 | H6: =Tbl_Ventes[[#This Row],[Quantité]]*Tbl_Ventes[[#This Row],[Prix Unitaire]] -> 4860 | I6: 75 | J6: =Tbl_Ventes[[#This Row],[Quantité]]*Tbl_Ventes[[#This Row],[Coût Unitaire Direct]] -> 3375 | K6: =Tbl_Ventes[[#This Row],[Chiffre d''Affaires]]-Tbl_Ventes[[#This Row],[Coût Direct Total]] -> 1485 | L6: =Tbl_Ventes[[#This Row],[Marge]]/Tbl_Ventes[[#This Row],[Chiffre d''Affaires]] -> 0.30555556 | M6: =_xlfn.XLOOKUP(Tbl_Ventes[[#This Row],[ID Client]],Tbl_Clients[Client ID],Tbl_Clients[Client Name]) -> Dauphiné Composants | N6: =_xlfn.XLOOKUP(Tbl_Ventes[[#This Row],[ID Client]],Tbl_Clients[Client ID],Tbl_Clients[Sector]) -> Automobile | O6: =_xlfn.XLOOKUP(Tbl_Ventes[[#This Row],[ID Client]],Tbl_Clients[Client ID],Tbl_Clients[Account Manager]) -> Camille Dubois
A7: V006 | B7: 45690 | C7: C006 | D7: Nord | E7: Accessoires | F7: 150 | G7: 19 | H7: =Tbl_Ventes[[#This Row],[Quantité]]*Tbl_Ventes[[#This Row],[Prix Unitaire]] -> 2850 | I7: 12 | J7: =Tbl_Ventes[[#This Row],[Quantité]]*Tbl_Ventes[[#This Row],[Coût Unitaire Direct]] -> 1800 | K7: =Tbl_Ventes[[#This Row],[Chiffre d''Affaires]]-Tbl_Ventes[[#This Row],[Coût Direct Total]] -> 1050 | L7: =Tbl_Ventes[[#This Row],[Marge]]/Tbl_Ventes[[#This Row],[Chiffre d''Affaires]] -> 0.36842105 | M7: =_xlfn.XLOOKUP(Tbl_Ventes[[#This Row],[ID Client]],Tbl_Clients[Client ID],Tbl_Clients[Client Name]) -> Nortec Machines | N7: =_xlfn.XLOOKUP(Tbl_Ventes[[#This Row],[ID Client]],Tbl_Clients[Client ID],Tbl_Clients[Sector]) -> Machines-outils | O7: =_xlfn.XLOOKUP(Tbl_Ventes[[#This Row],[ID Client]],Tbl_Clients[Client ID],Tbl_Clients[Account Manager]) -> Sophie Lenoir
A8: V007 | B8: 45693 | C8: C007 | D8: Sud | E8: Composants | F8: 110 | G8: 44 | H8: =Tbl_Ventes[[#This Row],[Quantité]]*Tbl_Ventes[[#This Row],[Prix Unitaire]] -> 4840 | I8: 31 | J8: =Tbl_Ventes[[#This Row],[Quantité]]*Tbl_Ventes[[#This Row],[Coût Unitaire Direct]] -> 3410 | K8: =Tbl_Ventes[[#This Row],[Chiffre d''Affaires]]-Tbl_Ventes[[#This Row],[Coût Direct Total]] -> 1430 | L8: =Tbl_Ventes[[#This Row],[Marge]]/Tbl_Ventes[[#This Row],[Chiffre d''Affaires]] -> 0.29545455 | M8: =_xlfn.XLOOKUP(Tbl_Ventes[[#This Row],[ID Client]],Tbl_Clients[Client ID],Tbl_Clients[Client Name]) -> Alpina Métallurgie | N8: =_xlfn.XLOOKUP(Tbl_Ventes[[#This Row],[ID Client]],Tbl_Clients[Client ID],Tbl_Clients[Sector]) -> Métallurgie | O8: =_xlfn.XLOOKUP(Tbl_Ventes[[#This Row],[ID Client]],Tbl_Clients[Client ID],Tbl_Clients[Account Manager]) -> Julien Marchand
A9: V008 | B9: 45696 | C9: C008 | D9: Sud | E9: Modules | F9: 55 | G9: 112 | H9: =Tbl_Ventes[[#This Row],[Quantité]]*Tbl_Ventes[[#This Row],[Prix Unitaire]] -> 6160 | I9: 80 | J9: =Tbl_Ventes[[#This Row],[Quantité]]*Tbl_Ventes[[#This Row],[Coût Unitaire Direct]] -> 4400 | K9: =Tbl_Ventes[[#This Row],[Chiffre d''Affaires]]-Tbl_Ventes[[#This Row],[Coût Direct Total]] -> 1760 | L9: =Tbl_Ventes[[#This Row],[Marge]]/Tbl_Ventes[[#This Row],[Chiffre d''Affaires]] -> 0.28571429 | M9: =_xlfn.XLOOKUP(Tbl_Ventes[[#This Row],[ID Client]],Tbl_Clients[Client ID],Tbl_Clients[Client Name]) -> Lyonnaise Câblage | N9: =_xlfn.XLOOKUP(Tbl_Ventes[[#This Row],[ID Client]],Tbl_Clients[Client ID],Tbl_Clients[Sector]) -> Électronique | O9: =_xlfn.XLOOKUP(Tbl_Ventes[[#This Row],[ID Client]],Tbl_Clients[Client ID],Tbl_Clients[Account Manager]) -> Camille Dubois
A10: V009 | B10: 45699 | C10: C009 | D10: Nord | E10: Accessoires | F10: 180 | G10: 18 | H10: =Tbl_Ventes[[#This Row],[Quantité]]*Tbl_Ventes[[#This Row],[Prix Unitaire]] -> 3240 | I10: 14 | J10: =Tbl_Ventes[[#This Row],[Quantité]]*Tbl_Ventes[[#This Row],[Coût Unitaire Direct]] -> 2520 | K10: =Tbl_Ventes[[#This Row],[Chiffre d''Affaires]]-Tbl_Ventes[[#This Row],[Coût Direct Total]] -> 720 | L10: =Tbl_Ventes[[#This Row],[Marge]]/Tbl_Ventes[[#This Row],[Chiffre d''Affaires]] -> 0.22222222 | M10: =_xlfn.XLOOKUP(Tbl_Ventes[[#This Row],[ID Client]],Tbl_Clients[Client ID],Tbl_Clients[Client Name]) -> Picardie Assemblage | N10: =_xlfn.XLOOKUP(Tbl_Ventes[[#This Row],[ID Client]],Tbl_Clients[Client ID],Tbl_Clients[Sector]) -> Automobile | O10: =_xlfn.XLOOKUP(Tbl_Ventes[[#This Row],[ID Client]],Tbl_Clients[Client ID],Tbl_Clients[Account Manager]) -> Sophie Lenoir
A11: V010 | B11: 45702 | C11: C010 | D11: Export | E11: Composants | F11: 200 | G11: 47 | H11: =Tbl_Ventes[[#This Row],[Quantité]]*Tbl_Ventes[[#This Row],[Prix Unitaire]] -> 9400 | I11: 34 | J11: =Tbl_Ventes[[#This Row],[Quantité]]*Tbl_Ventes[[#This Row],[Coût Unitaire Direct]] -> 6800 | K11: =Tbl_Ventes[[#This Row],[Chiffre d''Affaires]]-Tbl_Ventes[[#This Row],[Coût Direct Total]] -> 2600 | L11: =Tbl_Ventes[[#This Row],[Marge]]/Tbl_Ventes[[#This Row],[Chiffre d''Affaires]] -> 0.27659574 | M11: =_xlfn.XLOOKUP(Tbl_Ventes[[#This Row],[ID Client]],Tbl_Clients[Client ID],Tbl_Clients[Client Name]) -> Global Export Partners | N11: =_xlfn.XLOOKUP(Tbl_Ventes[[#This Row],[ID Client]],Tbl_Clients[Client ID],Tbl_Clients[Sector]) -> Négoce international | O11: =_xlfn.XLOOKUP(Tbl_Ventes[[#This Row],[ID Client]],Tbl_Clients[Client ID],Tbl_Clients[Account Manager]) -> Camille Dubois
A12: V011 | B12: 45706 | C12: C001 | D12: Sud | E12: Modules | F12: 70 | G12: 109 | H12: =Tbl_Ventes[[#This Row],[Quantité]]*Tbl_Ventes[[#This Row],[Prix Unitaire]] -> 7630 | I12: 76 | J12: =Tbl_Ventes[[#This Row],[Quantité]]*Tbl_Ventes[[#This Row],[Coût Unitaire Direct]] -> 5320 | K12: =Tbl_Ventes[[#This Row],[Chiffre d''Affaires]]-Tbl_Ventes[[#This Row],[Coût Direct Total]] -> 2310 | L12: =Tbl_Ventes[[#This Row],[Marge]]/Tbl_Ventes[[#This Row],[Chiffre d''Affaires]] -> 0.30275229 | M12: =_xlfn.XLOOKUP(Tbl_Ventes[[#This Row],[ID Client]],Tbl_Clients[Client ID],Tbl_Clients[Client Name]) -> Auvergne Automotive Systems | N12: =_xlfn.XLOOKUP(Tbl_Ventes[[#This Row],[ID Client]],Tbl_Clients[Client ID],Tbl_Clients[Sector]) -> Automobile | O12: =_xlfn.XLOOKUP(Tbl_Ventes[[#This Row],[ID Client]],Tbl_Clients[Client ID],Tbl_Clients[Account Manager]) -> Julien Marchand
A13: V012 | B13: 45709 | C13: C002 | D13: Sud | E13: Accessoires | F13: 160 | G13: 18 | H13: =Tbl_Ventes[[#This Row],[Quantité]]*Tbl_Ventes[[#This Row],[Prix Unitaire]] -> 2880 | I13: 13 | J13: =Tbl_Ventes[[#This Row],[Quantité]]*Tbl_Ventes[[#This Row],[Coût Unitaire Direct]] -> 2080 | K13: =Tbl_Ventes[[#This Row],[Chiffre d''Affaires]]-Tbl_Ventes[[#This Row],[Coût Direct Total]] -> 800 | L13: =Tbl_Ventes[[#This Row],[Marge]]/Tbl_Ventes[[#This Row],[Chiffre d''Affaires]] -> 0.27777778 | M13: =_xlfn.XLOOKUP(Tbl_Ventes[[#This Row],[ID Client]],Tbl_Clients[Client ID],Tbl_Clients[Client Name]) -> Rhône Aérostructures | N13: =_xlfn.XLOOKUP(Tbl_Ventes[[#This Row],[ID Client]],Tbl_Clients[Client ID],Tbl_Clients[Sector]) -> Aéronautique | O13: =_xlfn.XLOOKUP(Tbl_Ventes[[#This Row],[ID Client]],Tbl_Clients[Client ID],Tbl_Clients[Account Manager]) -> Camille Dubois
... A61: V060 | B61: 45860 | C61: C010 | D61: Export | E61: Accessoires | F61: 215 | G61: 19 | H61: =Tbl_Ventes[[#This Row],[Quantité]]*Tbl_Ventes[[#This Row],[Prix Unitaire]] -> 4085 | I61: 14 | J61: =Tbl_Ventes[[#This Row],[Quantité]]*Tbl_Ventes[[#This Row],[Coût Unitaire Direct]] -> 3010 | K61: =Tbl_Ventes[[#This Row],[Chiffre d''Affaires]]-Tbl_Ventes[[#This Row],[Coût Direct Total]] -> 1075 | L61: =Tbl_Ventes[[#This Row],[Marge]]/Tbl_Ventes[[#This Row],[Chiffre d''Affaires]] -> 0.26315789 | M61: =_xlfn.XLOOKUP(Tbl_Ventes[[#This Row],[ID Client]],Tbl_Clients[Client ID],Tbl_Clients[Client Name]) -> Global Export Partners | N61: =_xlfn.XLOOKUP(Tbl_Ventes[[#This Row],[ID Client]],Tbl_Clients[Client ID],Tbl_Clients[Sector]) -> Négoce international | O61: =_xlfn.XLOOKUP(Tbl_Ventes[[#This Row],[ID Client]],Tbl_Clients[Client ID],Tbl_Clients[Account Manager]) -> Camille Dubois

Sheet Analyse_Rentabilité_Produit
A3: Row Labels | B3: CA Total | C3: Marge Total | D3: Total Taux de Marge Réel
A4: Modules | B4: 117702 | C4: 34913 | D4: 0.29662198
A5: Composants | B5: 108734 | C5: 30163 | D5: 0.27740173
A6: Accessoires | B6: 63023 | C6: 19000 | D6: 0.30147724
A7: Grand Total | B7: 289459 | C7: 84076 | D7: 0.2904591
A10: Produits | B10: CA Total | C10: Marge Total | D10: Total des Taux de Marge Réel
A11: Modules | B11: 117702 | C11: 34913 | D11: 0.29662198
A12: Composants | B12: 108734 | C12: 30163 | D12: 0.27740173
A13: Accessoires | B13: 63023 | C13: 19000 | D13: 0.30147724

Sheet Analyse_Rentabilité_Client
A3: Row Labels | B3: CA Total | C3: total de Marge | D3: Total de Taux de Marge Réel Clients | G3: Global Export Partners | H3: 35917 | I3: 9729 | J3: 0.27087452
A4: Global Export Partners | B4: 35917 | C4: 9729 | D4: 0.27087452 | G4: Auvergne Automotive Systems | H4: 32084 | I4: 9440 | J4: 0.29422765
A5: Auvergne Automotive Systems | B5: 32084 | C5: 9440 | D5: 0.29422765 | G5: Rhône Aérostructures | H5: 29960 | I5: 8587 | J5: 0.28661549
A6: Rhône Aérostructures | B6: 29960 | C6: 8587 | D6: 0.28661549 | G6: Alpina Métallurgie | H6: 29477 | I6: 8477 | J6: 0.28758015
A7: Alpina Métallurgie | B7: 29477 | C7: 8477 | D7: 0.28758015 | G7: Nortec Machines | H7: 27383 | I7: 8364 | J7: 0.30544498
A8: Nortec Machines | B8: 27383 | C8: 8364 | D8: 0.30544498 | G8: Dauphiné Composants | H8: 28149 | I8: 8252 | J8: 0.29315429
A9: Dauphiné Composants | B9: 28149 | C9: 8252 | D9: 0.29315429 | G9: Norbatir Industries | H9: 27121 | I9: 8094 | J9: 0.29844032
A10: Norbatir Industries | B10: 27121 | C10: 8094 | D10: 0.29844032 | G10: Lyonnaise Câblage | H10: 27184 | I10: 7972 | J10: 0.29326074
A11: Lyonnaise Câblage | B11: 27184 | C11: 7972 | D11: 0.29326074 | G11: Picardie Assemblage | H11: 27176 | I11: 7740 | J11: 0.28481013
